Workbook

Sheet Angelica
A1: Angelica Lopez
B5: Week of 26/02/2018 | C5: Start | D5: Finish | E5: Hrs worked | F5: Total Pay | G5: Description
B6: Monday
B7: Tuesday
B8: Wednesday
B9: Thursday | C9: 0.54166667 | D9: 0.625 | E9: 2
B10: Friday | C10: 0.54166667 | D10: 0.625 | E10: 2
B11: Saturday
B12: Sunday
B16: Week of 05/03/2018 | C16: Start | D16: Finish | E16: Hrs worked | F16: Total Pay | G16: Description
B17: Monday
B18: Tuesday
B19: Wednesday | E19: 3
B20: Thursday | C20: 0.39583333 | D20: 0.45833333 | E20: 1.5
C21: 0.54166667 | D21: 0.625 | E21: 2
B22: Friday
B23: Saturday
B24: Sunday
E25: =SUM(E9:E10,E19:E21) -> 10.5
A27: before this point all work was PAID IN VOUCHERS…
B29: ANTHONY's INPUT
B34: Week of 12/03/2018 | C34: Start | D34: Finish | E34: Hrs worked | F34: Hrs Paid | G34: Description | H34: Payment received
A35: 12 | B35: Monday
A36: 13 | B36: Tuesday | C36: 0.375 | D36: 0.5 | E36: 3 | G36: Seaching by courses using different terminology to list the list of statistical courses offered at UC. The whole dataset is complete it
A37: 14 | B37: Wednesday
A38: 15 | B38: Thursday | C38: 0.54166667 | D38: 0.625 | E38: 2 | G38: Regular Drop in
A39: 16 | B39: Friday | C39: 0.375 | D39: 0.5 | E39: 3 | G39: organized files. In dropbox. Reading and organized the whole files and build a dataset of files.
A40: 17 | B40: Saturday
A41: 18 | B41: Sunday
B42: TOTAL | E42: =SUM(E35:E41) -> 8 | F42: Hours submitted | G42: Hours owing
A43: Tuesday 21 March | B43: Payday | E43: =SUM(E35:E39) -> 8 | F43: =SUM(1*Angelica_hist!G3) -> 5 | G43: =SUM(E43-F43) -> 3
B46: Week of 19/03/2018 | C46: Start | D46: Finish | E46: Hrs worked | F46: Hrs Paid | G46: Description | H46: Payment received
A47: 19 | B47: Monday
A48: 20 | B48: Tuesday
A49: 21 | B49: Wednesday
A50: 22 | B50: Thursday | C50: 0.54166667 | D50: 0.625 | E50: 2 | G50: Regular Drop in
A51: 23 | B51: Friday | C51: 0.375 | D51: 0.45833333 | E51: 2 | G51: Statistical Network project process and possible tasks. In dropbox.
A52: 24 | B52: Saturday
A53: 25 | B53: Sunday
B54: TOTAL | E54: =SUM(E46:E53) -> 4
...

Sheet Angelica_hist
A1: Period End Date | B1: Surname | C1: Preferred Name | D1: GL Record Type Description | E1: Account Number Prefix | F1: Paycode | G1: Salary Hours | H1: Amt$
A2: 43180
A3: 43180 | B3: LOPEZ | C3: Angelica | D3: Earnings | E3: 50002 | F3: Rate P - Other | G3: 5 | H3: 226.4
A4: 43180 | B4: LOPEZ | C4: Angelica | D4: Oncosts | E4: 50018 | F4: Oncosts | H4: 15.51
A5: 43180 | B5: LOPEZ | C5: Angelica | D5: Oncosts | E5: 50020 | F5: Oncosts | H5: 1.47
A6: 43180 | B6: LOPEZ | C6: Angelica | D6: Oncosts | E6: 50021 | F6: Oncosts | H6: 2.83
A7: 43180 | B7: LOPEZ | C7: Angelica | D7: Subsidies | E7: 50016 | F7: Super | H7: 21.51
A8: 43194
A9: 43194 | B9: LOPEZ | C9: Angelica | D9: Earnings | E9: 50002 | F9: Rate P - Other | G9: 5 | H9: 226.4
A10: 43194 | B10: LOPEZ | C10: Angelica | D10: Oncosts | E10: 50018 | F10: Oncosts | H10: 15.51
A11: 43194 | B11: LOPEZ | C11: Angelica | D11: Oncosts | E11: 50021 | F11: Oncosts | H11: 2.83
A12: 43208 | B12: LOPEZ | C12: Angelica | D12: Oncosts | E12: 50020 | F12: Oncosts | H12: 1.47
A13: 43208 | B13: LOPEZ | C13: Angelica | D13: Subsidies | E13: 50016 | F13: Super | H13: 21.51
A14: 43222
A15: 43222 | B15: LOPEZ | C15: Angelica | D15: Earnings | E15: 50002 | F15: Rate P - Other | G15: 10 | H15: 452.78
A16: 43222 | B16: LOPEZ | C16: Angelica | D16: Oncosts | E16: 50018 | F16: Oncosts | H16: 31.02
A17: 43222 | B17: LOPEZ | C17: Angelica | D17: Oncosts | E17: 50020 | F17: Oncosts | H17: 2.95
A18: 43222 | B18: LOPEZ | C18: Angelica | D18: Oncosts | E18: 50021 | F18: Oncosts | H18: 5.66
A19: 43222 | B19: LOPEZ | C19: Angelica | D19: Subsidies | E19: 50016 | F19: Super | H19: 43.01
A20: 43236
A21: 43236 | B21: LOPEZ | C21: Angelica | D21: Earnings | E21: 50002 | F21: Rate O - Marking | G21: 22.5 | H21: 1215.87
A22: 43236 | B22: LOPEZ | C22: Angelica | D22: Oncosts | E22: 50018 | F22: Oncosts | H22: 83.29
A23: 43236 | B23: LOPEZ | C23: Angelica | D23: Oncosts | E23: 50020 | F23: Oncosts | H23: 7.91
A24: 43236 | B24: LOPEZ | C24: Angelica | D24: Oncosts | E24: 50021 | F24: Oncosts | H24: 15.19
A25: 43236 | B25: LOPEZ | C25: Angelica | D25: Subsidies | E25: 50016 | F25: Super | H25: 115.51
A26: 43250
A27: 43250 | B27: LOPEZ | C27: Angelica | D27: Earnings | E27: 50002 | F27: Rate O - Marking | G27: -22.5 | H27: -1215.87
A28: 43250 | B28: LOPEZ | C28: Angelica | D28: Earnings | E28: 50002 | F28: Rate P - Other | G28: 52.5 | H28: 2377.15
A29: 43250 | B29: LOPEZ | C29: Angelica | D29: Earnings | E29: 50002 | F29: Rate Q - Other | G29: 25 | H29: 1350.96
A30: 43250 | B30: LOPEZ | C30: Angelica | D30: Oncosts | E30: 50018 | F30: Oncosts | H30: 172.08
A31: 43250 | B31: LOPEZ | C31: Angelica | D31: Oncosts | E31: 50020 | F31: Oncosts | H31: 17.82
A32: 43250 | B32: LOPEZ | C32: Angelica | D32: Oncosts | E32: 50021 | F32: Oncosts | H32: 31.4
A33: 43250 | B33: LOPEZ | C33: Angelica | D33: Subsidies | E33: 50016 | F33: Super | H33: 260.17
A34: 43264
A35: 43264 | B35: LOPEZ | C35: Angelica | D35: Earnings | E35: 50002 | F35: Rate P - Other | G35: 30 | H35: 1358.37
A36: 43264 | B36: LOPEZ | C36: Angelica | D36: Oncosts | E36: 50018 | F36: Oncosts | H36: 93.04
A37: 43264 | B37: LOPEZ | C37: Angelica | D37: Oncosts | E37: 50020 | F37: Oncosts | H37: 8.84
A38: 43264 | B38: LOPEZ | C38: Angelica | D38: Oncosts | E38: 50021 | F38: Oncosts | H38: 16.98
A39: 43264 | B39: LOPEZ | C39: Angelica | D39: Subsidies | E39: 50016 | F39: Super | H39: 129.05
A40: 43278
...
