Workbook

Sheet Finalised_timesheet
A1: Overall proposed timesheet | H1: Stage | I1: Time | J1: Status | K1: Due date
A2: For the next set of Acidemic contracts: Stage three (July 2018 - September 2018) | H2: Stage one | I2: 1st February - 13th May | J2: DONE
H3: Stage two | I3: 14th May - 1 July | J3: DONE
H4: Stage three | I4: 2 July 2018 - 1st September 2018 | J4: CURRENT | K4: 31st July 2018
H5: Stage four | I5: 2nd September 2018 - 31st December 2018 | J5: DRAFT NEEDED | K5: 28th August 2018
A7: The extra two weeks of the contract are included in the finalised timesheets under each advisor
A9: 23-29 July 2018 | B9: WS=W1 | C9: Monday | D9: Tuesday | E9: Wednesday | F9: Thursday | G9: Friday | H9: Saturday | I9: Sunday | J9: Total
B10: Anthony | E10: 4.5 | F10: 5 | G10: 5 | H10: 4 | I10: 5 | J10: =SUM(C10:I10) -> 23.5 | K10: NOTE: Must have timesheet to be pay this by Monday 30th
C11: 9am - 5pm office (3C3)
B12: Margarita | C12: 0 | D12: 0 | E12: RDO | F12: 2 | G12: 0 | J12: =SUM(C12:I12) -> 2
C13: One-on-one | F13: Drop-in session | G13: One-on-one
B14: Angelica | C14: RDO | D14: RDO | E14: RDO | F14: RDO | G14: RDO | I14: 8 | J14: =SUM(C14:I14) -> 8
H15: 5hrs over weekend or evenings with previous researchers
B16: Kyle | C16: RDO | D16: RDO | E16: RDO | F16: 2 | G16: RDO | J16: =SUM(C16:I16) -> 2
F17: Drop-in session
B18: Researcher development
B19: Total | C19: 2 | D19: 4 | E19: 2 | F19: 7 | G19: 4 | J19: =SUM(J10:J18) -> 35.5
A22: 30 July-5 August 2018 | B22: WS=W2 | C22: Monday | D22: Tuesday | E22: Wednesday | F22: Thursday | G22: Friday | H22: Saturday | I22: Sunday | J22: Total
B23: Anthony | C23: 2 | D23: 3 | J23: =SUM(C23:I23) -> 5 | K23: NOTE: Must have timesheet to be pay this by Monday 6th
C24: 9am - 5pm office (3C3)
B25: Margarita | C25: 2 | D25: 0 | E25: RDO | F25: 3 | G25: 2 | J25: =SUM(C25:I25) -> 7
C26: One-on-one | F26: 9am - 4.30pm (30min break) | G26: One-on-one
B27: Angelica | C27: RDO | D27: RDO | E27: RDO | F27: RDO | G27: RDO | I27: 6 | J27: =SUM(C27:I27) -> 6
H28: 5hrs over weekend or evenings with previous researchers
B29: New Staff 1 | F29: 2 | J29: 2
F30: Drop-in session
B31: Kyle | C31: RDO | D31: RDO | E31: RDO | F31: 2 | G31: RDO | J31: =SUM(C31:I31) -> 2
F32: Drop-in session
B33: Researcher development | J33: =SUM(C32:I32) -> 0
B34: Total | C34: 2 | D34: 4 | E34: 2 | F34: 7 | G34: 4 | J34: =SUM(J23:J33) -> 22
A37: 6-12 August 2018 | B37: WS=W3 | C37: Monday | D37: Tuesday | E37: Wednesday | F37: Thursday | G37: Friday | H37: Saturday | I37: Sunday | J37: Total
B38: Anthony | D38: 0.5 | J38: =SUM(C38:I38) -> 0.5 | K38: NOTE: Must have timesheet to be pay this by Monday 13th
C39: 9am - 5pm office (3C3)
B40: Margarita | C40: 2 | D40: 4 | E40: RDO | F40: 7 | G40: 2 | J40: =SUM(C40:I40) -> 15
C41: One-on-one | F41: 9am - 4.30pm (30min break) | G41: One-on-one
B42: New Staff 1 | C42: RDO | D42: RDO | E42: RDO | F42: 2 | G42: RDO | H42: Over weekend or evenings as needed | J42: =SUM(C42:I42) -> 2
F43: Drop-in session
B44: Kyle | C44: RDO | D44: RDO | E44: RDO | F44: 2 | G44: RDO | J44: =SUM(C44:I44) -> 2
F45: Drop-in session
B46: Angelica | I46: 5 | J46: =SUM(H46:I46) -> 5
...

Sheet Final_Anthony
A1: Anthony Davidson
B5: Payday | C5: Hours submitted | D5: Hours owing
A6: Tuesday 24th January | B6: 43124 | C6: =SUM([1]Anthony_hist!G3) -> 12.5 | D6: 73.5
A7: Tuesday 7th Febuary | B7: 43138 | C7: =SUM([1]Anthony_hist!G9) -> 73.5 | D7: =SUM(D6-C7) -> 0
B9: Week of 26/02/2018 | C9: Start | D9: Finish | E9: Hrs worked | F9: Total Pay | G9: General | H9: Details
B10: Monday
B11: Tuesday
B12: Wednesday
B13: Thursday | C13: 0.54166667 | D13: 0.625 | E13: 2 | G13: Drop-in
C14: 0.625 | D14: 0.66666667 | E14: 1 | G14: Jenni
B15: Friday | C15: 0.54166667 | D15: 0.625 | E15: 2 | G15: Ant+ Angelica
B16: Saturday | C16: 0.54166667 | D16: 0.58333333 | E16: 1 | G16: Admin | H16: Emailing network people
B17: Sunday | C17: 0.375 | D17: 0.625 | E17: 6 | G17: Haysem one-on-one. | H17: Regression and research management
B18: TOTAL | E18: =SUM(E10:E17) -> 12 | F18: Hours submitted | G18: Hours owing
A19: Tuesday 7th March | B19: Payday | E19: =SUM(E11,E18) -> 12 | F19: =SUM([1]Anthony_hist!G15) -> 6 | G19: =SUM(E19+D7)-F19 -> 6
B22: Week of 05/03/2018 | C22: Start | D22: Finish | E22: Hrs worked | F22: Total Pay | G22: Description
B23: Monday | C23: 0.41666667 | D23: 0.45833333 | E23: 1 | G23: Admin(emails)
B24: Tuesday | C24: 0.41666667 | D24: 0.45833333 | E24: 1 | G24: Admin(emails)
C25: 0.52083333 | D25: 0.54166667 | E25: 0.5 | G25: Lecture
C26: 0.64583333 | D26: 0.6875 | E26: 1 | G26: Contracts meeting and admin
B27: Wednesday | C27: 0.5625 | D27: 0.66666667 | E27: 3.5 | G27: Network building
C28: 0.72916667 | D28: 0.9375 | E28: 5 | G28: Haysem
C29: 0.97916667 | D29: 0.052083333 | E29: 1.75 | G29: Admin(emails)
B30: Thursday | C30: 0.45833333 | D30: 0.5 | E30: 1 | G30: Admin meeting maths&stats
C31: 0.5 | D31: 0.625 | E31: 3 | G31: Shalini one-on-one
C32: 0.625 | D32: 0.66666667 | E32: 1 | G32: Admin meeting contracts + anna
B33: Friday | E33: =SUM(D33-C33) -> 0
B34: Saturday | E34: =SUM(D34-C34) -> 0
B35: Sunday | E35: =SUM(D35-C35) -> 0
A36: MISSED | B36: TOTAL | E36: =SUM(E23:E35) -> 18.75 | F36: Hours owing
F37: 0 | G37: =SUM(E36,G19) -> 24.75
A38: Before this point all work was under trial but have carryover tooooo
B40: Week of 12/03/2018 | C40: Start | D40: Finish | E40: Hrs worked | F40: Hrs Paid | G40: Description | H40: Notes
A41: 12 | B41: Monday | C41: 0.5 | D41: 0.625 | E41: 2 | G41: Jackson about publication options for network (Public holiday so caught up on this work instead)
A42: 13 | B42: Tuesday | C42: 0.41666667 | D42: 0.54166667 | E42: 3 | G42: Admin
A43: 14 | B43: Wednesday
A44: 15 | B44: Thursday | C44: 0.5 | D44: 0.58333333 | E44: 2 | G44: Admin
A45: 16 | B45: Friday
A46: 17 | B46: Saturday
A47: 18 | B47: Sunday | H47: This includes hours from previous contract that will still be in this contracts hours for now
...

Sheet Final_Angelica
A1: Angelica Lopez
B5: Week of 26/02/2018 | C5: Start | D5: Finish | E5: Hrs worked | F5: Total Pay | G5: Description
B6: Monday
B7: Tuesday
B8: Wednesday
B9: Thursday | C9: 0.54166667 | D9: 0.625 | E9: 2
B10: Friday | C10: 0.54166667 | D10: 0.625 | E10: 2
B11: Saturday
B12: Sunday
B16: Week of 05/03/2018 | C16: Start | D16: Finish | E16: Hrs worked | F16: Total Pay | G16: Description
B17: Monday
B18: Tuesday
B19: Wednesday | E19: 3
B20: Thursday | C20: 0.39583333 | D20: 0.45833333 | E20: 1.5
C21: 0.54166667 | D21: 0.625 | E21: 2
B22: Friday
B23: Saturday
B24: Sunday
E25: =SUM(E9:E10,E19:E21) -> 10.5
A27: before this point all work was PAID IN VOUCHERS…
B29: ANTHONY's INPUT
B34: Week of 12/03/2018 | C34: Start | D34: Finish | E34: Hrs worked | F34: Hrs Paid | G34: Description | H34: Payment received
A35: 12 | B35: Monday
A36: 13 | B36: Tuesday | C36: 0.375 | D36: 0.5 | E36: 3 | G36: Seaching by courses using different terminology to list the list of statistical courses offered at UC. The whole dataset is complete it
A37: 14 | B37: Wednesday
A38: 15 | B38: Thursday | C38: 0.54166667 | D38: 0.625 | E38: 2 | G38: Regular Drop in
A39: 16 | B39: Friday | C39: 0.375 | D39: 0.5 | E39: 3 | G39: organized files. In dropbox. Reading and organized the whole files and build a dataset of files.
A40: 17 | B40: Saturday
A41: 18 | B41: Sunday
B42: TOTAL | E42: =SUM(E35:E41) -> 8 | F42: Hours submitted | G42: Hours owing
A43: Tuesday 21 March | B43: Payday | E43: =SUM(E35:E39) -> 8 | F43: =SUM(1*[2]Angelica_hist!G3) -> 5 | G43: =SUM(E43-F43) -> 3
B46: Week of 19/03/2018 | C46: Start | D46: Finish | E46: Hrs worked | F46: Hrs Paid | G46: Description | H46: Payment received
A47: 19 | B47: Monday
A48: 20 | B48: Tuesday
A49: 21 | B49: Wednesday
A50: 22 | B50: Thursday | C50: 0.54166667 | D50: 0.625 | E50: 2 | G50: Regular Drop in
A51: 23 | B51: Friday | C51: 0.375 | D51: 0.45833333 | E51: 2 | G51: Statistical Network project process and possible tasks. In dropbox.
A52: 24 | B52: Saturday
A53: 25 | B53: Sunday
B54: TOTAL | E54: =SUM(E46:E53) -> 4
...

Sheet Final_Marg
A1: Margarita
A8: ANTHONY's INPUT
A9: NEW CONTRACT
A11: END CONTRACT START A NEW ONE | B11: Week of 05/03/2018 | C11: Start | D11: Finish | E11: Hrs worked | F11: Total Pay | G11: Description | I11: Stage one | J11: 1st February - 13th May
A12: 4 | B12: Monday | C12: 0.625 | D12: 0.66666667 | E12: 1 | G12: Asking about job situation and lining up timetables | I12: Stage two | J12: 14th May - 1 July
A13: 5 | B13: Tuesday | I13: Stage three: Current | J13: 2 July 2018 - 1st September 2018
A14: 6 | B14: Wednesday | C14: 0.625 | D14: 0.66666667 | E14: 1 | G14: Meeting for contracts etc
A15: 7 | B15: Thursday
A16: 8
A17: 9 | B17: Friday
A18: 10 | B18: Saturday
A19: 11 | B19: Sunday
B20: TOTAL | E20: =SUM(E12:E19) -> 2
B22: Week of 12/03/2018 | C22: Start | D22: Finish | E22: Hrs worked | F22: Hrs Paid | G22: Description | H22: Payment received
A23: 12 | B23: Monday
A24: 13 | B24: Tuesday
A25: 14 | B25: Wednesday
A26: 15 | B26: Thursday
A27: 16 | B27: Friday
A28: 17 | B28: Saturday
A29: 18 | B29: Sunday
B30: TOTAL | E30: =SUM(E23:E29) -> 0 | F30: Hours submitted | G30: Hours owing
A31: Tuesday 21 March | B31: Payday | E31: =SUM(E30+E20) -> 2 | F31: =SUM(1*[3]Marg_hist!G3) -> 5 | G31: =SUM(E31+G20)-F31 -> -3
A32: 43180
B34: Week of 19/03/2018 | C34: Start | D34: Finish | E34: Hrs worked | F34: Hrs Paid | G34: Description | H34: Payment received
A35: 19 | B35: Monday
A36: 20 | B36: Tuesday
A37: 21 | B37: Wednesday
A38: 22 | B38: Thursday
A39: 23 | B39: Friday
A40: 24 | B40: Saturday
A41: 25 | B41: Sunday
B42: TOTAL | E42: =SUM(E34:E41) -> 0
B44: Week of 26/03/2018 | C44: Start | D44: Finish | E44: Hrs worked | F44: Total Pay | G44: Description
A45: 26 | B45: Monday
A46: 27 | B46: Tuesday
A47: 28 | B47: Wednesday 28 march
A48: 29 | B48: Thursday | C48: 0.5 | D48: 0.66666667 | E48: 4 | G48: Meeting / admin / emails
A49: 30 | B49: Friday
A50: 31 | B50: Saturday
...

Sheet Final_kyle
A1: Kyle Hemming
A2: Weekly roster
B3: Start | C3: Finish | D3: Hrs worked | E3: Total Pay | F3: Description
A4: Monday | G4: Kyle has been doing the drop-in sessions from the very beginning of the statistics network in 2017. There has been mininal variation in the timesheets or workload other than during transistion periods.
A5: Tuesday
A6: Wednesday
A7: Thursday | B7: 0.54166667 | C7: 0.125 | D7: 2 | F7: Drop-in session
A8: Friday
A9: Saturday
A10: Sunday
A11: TOTAL | D11: 2
A14: Submit paper forms | B14: Submit electronic | C14: Payday | D14: Hrs worked | E14: Hrs submitted | F14: Hrs paid | G14: NOTES
A15: Previous trial period……
C18: 11th January 2018 | D18: 4
C19: 25th January 2018 | D19: 4 | E19: =SUM(#REF!) -> #REF!
C20: 8th February 2018 | D20: 4 | E20: =SUM(#REF!) -> #REF! | G20: Back pay
C21: 22nd February 2018 | D21: 4
C22: 8th March 2018 | D22: 4 | E22: =SUM(#REF!) -> #REF!
C23: 22nd March 2018 | D23: 4 | E23: =SUM(#REF!) -> #REF!
C24: 5th April 2018 | D24: 4 | E24: =SUM(#REF!) -> #REF!
C25: 19th April 2018 | D25: 4 | E25: =SUM(#REF!) -> #REF!
C26: 3rd May 2018 | D26: 4 | E26: =SUM(#REF!) -> #REF! | G26: Pay screw-up
C27: 17th May 2018 | D27: 2 | E27: =SUM(#REF!) -> #REF! | G27: Pay screw-up
C28: 31st May 2018 | D28: 4 | E28: =SUM(#REF!) -> #REF!
C29: 14th June 2018 | D29: 4 | E29: =SUM(#REF!) -> #REF!
C30: 27th June 2018 | D30: 4 | E30: =SUM(#REF!) -> #REF!
C31: 11th July 2018 | D31: 4 | E31: =SUM(#REF!) -> #REF! | G31: Shut-up and write too…??
C32: 26th July 2018 | D32: 4 | E32: 4 | F32: 0 | G32: 4hours owing orginally
C33: 9th August 2018 | D33: 4 | E33: 0 | F33: 4
C34: 23rd August 2018 | D34: 4 | E34: 0 | F34: 4
C35: 6th September 2018 | E35: 0 | F35: 4
C36: 20th September 2018
C37: 4th October 2018
C38: 18th October 2018
C39: 1st November 2018
C40: 15th Novermber 2018
C41: 29th November 2018
C42: 13th December 2018
C43: 27th December 2018
A44: TOTALS | B44: Estimate | C44: TOTAL | D44: =SUM(D18:D43) -> 66 | E44: =SUM(E18:E43) -> #REF! | G44: Extra paid that shouldn't be there..Shutupand write etc…
...

Sheet Anthony
A1: NEW CONTRACT | O1: Monday
O2: Tuesday
A3: END CONTRACT START A NEW ONE | B3: Week of 05/03/2018 | C3: Start | D3: Finish | E3: Hrs worked | F3: Total Pay | G3: Description | I3: Stage one | J3: 1st February - 13th May | O3: Wednesday
A4: 4 | B4: Monday | C4: 0.625 | D4: 0.66666667 | E4: 1 | G4: Asking about job situation and lining up timetables | I4: Stage two | J4: 14th May - 1 July | O4: Thursday | P4: 0.54166667 | Q4: 0.625 | R4: 2 | T4: Drop-in
A5: 5 | B5: Tuesday | I5: Stage three: Current | J5: 2 July 2018 - 1st September 2018 | P5: 0.625 | Q5: 0.66666667 | R5: 1 | T5: Jenni
A6: 6 | B6: Wednesday | C6: 0.625 | D6: 0.66666667 | E6: 1 | G6: Meeting for contracts etc | O6: Friday | P6: 0.54166667 | Q6: 0.625 | R6: 2 | T6: Ant+ Angelica
A7: 7 | B7: Thursday | O7: Saturday | P7: 0.54166667 | Q7: 0.58333333 | R7: 1 | T7: Admin | U7: Emailing network people
A8: 8 | O8: Sunday | P8: 0.375 | Q8: 0.625 | R8: 6 | T8: Haysem one-on-one. | U8: Regression and research management
A9: 9 | B9: Friday | O9: TOTAL | R9: =SUM(R1:R8) -> 12
A10: 10 | B10: Saturday
A11: 11 | B11: Sunday
B12: TOTAL | E12: =SUM(E4:E11) -> 2 | G12: 2hrs owed | O12: Week of 05/03/2018 | P12: Start | Q12: Finish | R12: Hrs worked | S12: Total Pay | T12: Description
O13: Monday | P13: 0.41666667 | Q13: 0.45833333 | R13: 1 | T13: Admin(emails)
B14: Week of 12/03/2018 | C14: Start | D14: Finish | E14: Hrs worked | F14: Hrs Paid | G14: Description | H14: Payment received | O14: Tuesday | P14: 0.41666667 | Q14: 0.45833333 | R14: 1 | T14: Admin(emails)
A15: 12 | B15: Monday | P15: 0.52083333 | Q15: 0.54166667 | R15: 0.5 | T15: Lecture
A16: 13 | B16: Tuesday | P16: 0.64583333 | Q16: 0.6875 | R16: 1 | T16: Contracts meeting and admin
A17: 14 | B17: Wednesday | O17: Wednesday | P17: 0.5625 | Q17: 0.66666667 | R17: 3.5 | T17: Network building
A18: 15 | B18: Thursday | P18: 0.72916667 | Q18: 0.9375 | R18: 5 | T18: Haysem
A19: 16 | B19: Friday | P19: 0.97916667 | Q19: 0.052083333 | R19: 1.75 | T19: Admin(emails)
A20: 17 | B20: Saturday | O20: Thursday | P20: 0.45833333 | Q20: 0.5 | R20: 1 | T20: Admin meeting maths&stats
A21: 18 | B21: Sunday | P21: 0.5 | Q21: 0.625 | R21: 3 | T21: Shalini one-on-one
B22: TOTAL | E22: =SUM(E15:E21) -> 0 | G22: 2hrs owed | P22: 0.625 | Q22: 0.66666667 | R22: 1 | T22: Admin meeting contracts + anna
A23: Tuesday 21 March | B23: Payday | E23: =SUM(E15:E19, E4:E11) -> 2 | F23: 10hrs submitted | G23: 8hrs extra | H23: 10hrs paid | O23: Friday | R23: =SUM(Q23-P23) -> 0
O24: Saturday | R24: =SUM(Q24-P24) -> 0
O25: Sunday | R25: =SUM(Q25-P25) -> 0
B26: Week of 19/03/2018 | C26: Start | D26: Finish | E26: Hrs worked | F26: Hrs Paid | G26: Description | H26: Payment received | O26: TOTAL | R26: =SUM(R13:R25) -> 18.75
A27: 19 | B27: Monday | O27: PAID | S27: 30.75 hrs submitted 13/04/2018
A28: 20 | B28: Tuesday
A29: 21 | B29: Wednesday
A30: 22 | B30: Thursday | O30: Week of 12/03/2018 | P30: Start | Q30: Finish | R30: Hrs worked | S30: Total Pay | T30: Description
A31: 23 | B31: Friday | O31: Monday
A32: 24 | B32: Saturday | O32: Tuesday
A33: 25 | B33: Sunday | O33: Wednesday
B34: TOTAL | E34: =SUM(E26:E33) -> 0 | G34: 8hrs extra | O34: Thursday
O35: Friday
B36: Week of 26/03/2018 | C36: Start | D36: Finish | E36: Hrs worked | F36: Total Pay | G36: Description | O36: Saturday
A37: 26 | B37: Monday | O37: Sunday
A38: 27 | B38: Tuesday | O38: TOTAL | R38: 7
A39: 28 | B39: Wednesday 28 march
A40: 29 | B40: Thursday | C40: 0.5 | D40: 0.66666667 | E40: 4 | G40: Meeting / admin / emails
...

Sheet Anthony_hist
A1: Period End Date | B1: Surname | C1: Preferred Name | D1: GL Record Type Description | E1: Account Number Prefix | F1: Paycode | G1: Salary Hours | H1: Amt$
A2: 43124
A3: 43124 | B3: DAVIDSON | C3: Anthony | D3: Earnings | E3: 50007 | F3: Salary Casual | G3: 12.5 | H3: 716.91
A4: 43124 | B4: DAVIDSON | C4: Anthony | D4: Oncosts | E4: 50031 | F4: Oncosts | H4: 49.11
A5: 43124 | B5: DAVIDSON | C5: Anthony | D5: Oncosts | E5: 50032 | F5: Oncosts | H5: 4.67
A6: 43124 | B6: DAVIDSON | C6: Anthony | D6: Oncosts | E6: 50033 | F6: Oncosts | H6: 8.95
A7: 43124 | B7: DAVIDSON | C7: Anthony | D7: Subsidies | E7: 50027 | F7: Super | H7: 68.11
A8: 43138
A9: 43138 | B9: DAVIDSON | C9: Anthony | D9: Earnings | E9: 50007 | F9: Salary Casual | G9: 73.5 | H9: 4258.2
A10: 43138 | B10: DAVIDSON | C10: Anthony | D10: Oncosts | E10: 50031 | F10: Oncosts | H10: 291.7
A11: 43138 | B11: DAVIDSON | C11: Anthony | D11: Oncosts | E11: 50032 | F11: Oncosts | H11: 27.71
A12: 43138 | B12: DAVIDSON | C12: Anthony | D12: Oncosts | E12: 50033 | F12: Oncosts | H12: 53.22
A13: 43138 | B13: DAVIDSON | C13: Anthony | D13: Subsidies | E13: 50027 | F13: Super | H13: 404.53
A14: 43166
A15: 43166 | B15: DAVIDSON | C15: Anthony | D15: Earnings | E15: 50007 | F15: Salary Casual | G15: 6 | H15: 347.6
A16: 43166 | B16: DAVIDSON | C16: Anthony | D16: Oncosts | E16: 50031 | F16: Oncosts | H16: 23.81
A17: 43166 | B17: DAVIDSON | C17: Anthony | D17: Oncosts | E17: 50033 | F17: Oncosts | H17: 4.35
A18: 43180
A19: 43180 | B19: DAVIDSON | C19: Anthony | D19: Earnings | E19: 50007 | F19: Salary Casual | G19: 1 | H19: 57.93
A20: 43180 | B20: DAVIDSON | C20: Anthony | D20: Oncosts | E20: 50031 | F20: Oncosts | H20: 3.97
A21: 43180 | B21: DAVIDSON | C21: Anthony | D21: Oncosts | E21: 50033 | F21: Oncosts | H21: 0.72
A22: 43222
A23: 43222 | B23: DAVIDSON | C23: Anthony | D23: Earnings | E23: 50002 | F23: Rate P - Other | G23: 40.75 | H23: 1845.12
A24: 43222 | B24: DAVIDSON | C24: Anthony | D24: Oncosts | E24: 50018 | F24: Oncosts | H24: 126.39
A25: 43222 | B25: DAVIDSON | C25: Anthony | D25: Oncosts | E25: 50020 | F25: Oncosts | H25: 12.01
A26: 43222 | B26: DAVIDSON | C26: Anthony | D26: Oncosts | E26: 50021 | F26: Oncosts | H26: 23.06
A27: 43222 | B27: DAVIDSON | C27: Anthony | D27: Subsidies | E27: 50016 | F27: Super | H27: 175.29
A28: 43236
A29: 43236 | B29: DAVIDSON | C29: Anthony | D29: Earnings | E29: 50002 | F29: Rate P - Other | G29: 10 | H29: 452.79
A30: 43236 | B30: DAVIDSON | C30: Anthony | D30: Oncosts | E30: 50018 | F30: Oncosts | H30: 31.02
A31: 43236 | B31: DAVIDSON | C31: Anthony | D31: Oncosts | E31: 50020 | F31: Oncosts | H31: 2.95
A32: 43236 | B32: DAVIDSON | C32: Anthony | D32: Oncosts | E32: 50021 | F32: Oncosts | H32: 5.66
A33: 43236 | B33: DAVIDSON | C33: Anthony | D33: Subsidies | E33: 50016 | F33: Super | H33: 43.02
A34: 43250
A35: 43250 | B35: DAVIDSON | C35: Anthony | D35: Earnings | E35: 50002 | F35: Rate P - Other | G35: 65.5 | H35: 2965.78
A36: 43250 | B36: DAVIDSON | C36: Anthony | D36: Oncosts | E36: 50018 | F36: Oncosts | H36: 203.15
A37: 43250 | B37: DAVIDSON | C37: Anthony | D37: Oncosts | E37: 50020 | F37: Oncosts | H37: 19.3
A38: 43250 | B38: DAVIDSON | C38: Anthony | D38: Oncosts | E38: 50021 | F38: Oncosts | H38: 37.07
A39: 43250 | B39: DAVIDSON | C39: Anthony | D39: Subsidies | E39: 50016 | F39: Super | H39: 281.75
A40: 43264
...

Sheet Angelica_hist
A1: Period End Date | B1: Surname | C1: Preferred Name | D1: GL Record Type Description | E1: Account Number Prefix | F1: Paycode | G1: Salary Hours | H1: Amt$
A2: 43180
A3: 43180 | B3: LOPEZ | C3: Angelica | D3: Earnings | E3: 50002 | F3: Rate P - Other | G3: 5 | H3: 226.4
A4: 43180 | B4: LOPEZ | C4: Angelica | D4: Oncosts | E4: 50018 | F4: Oncosts | H4: 15.51
A5: 43180 | B5: LOPEZ | C5: Angelica | D5: Oncosts | E5: 50020 | F5: Oncosts | H5: 1.47
A6: 43180 | B6: LOPEZ | C6: Angelica | D6: Oncosts | E6: 50021 | F6: Oncosts | H6: 2.83
A7: 43180 | B7: LOPEZ | C7: Angelica | D7: Subsidies | E7: 50016 | F7: Super | H7: 21.51
A8: 43194
A9: 43194 | B9: LOPEZ | C9: Angelica | D9: Earnings | E9: 50002 | F9: Rate P - Other | G9: 5 | H9: 226.4
A10: 43194 | B10: LOPEZ | C10: Angelica | D10: Oncosts | E10: 50018 | F10: Oncosts | H10: 15.51
A11: 43194 | B11: LOPEZ | C11: Angelica | D11: Oncosts | E11: 50021 | F11: Oncosts | H11: 2.83
A12: 43208 | B12: LOPEZ | C12: Angelica | D12: Oncosts | E12: 50020 | F12: Oncosts | H12: 1.47
A13: 43208 | B13: LOPEZ | C13: Angelica | D13: Subsidies | E13: 50016 | F13: Super | H13: 21.51
A14: 43222
A15: 43222 | B15: LOPEZ | C15: Angelica | D15: Earnings | E15: 50002 | F15: Rate P - Other | G15: 10 | H15: 452.78
A16: 43222 | B16: LOPEZ | C16: Angelica | D16: Oncosts | E16: 50018 | F16: Oncosts | H16: 31.02
A17: 43222 | B17: LOPEZ | C17: Angelica | D17: Oncosts | E17: 50020 | F17: Oncosts | H17: 2.95
A18: 43222 | B18: LOPEZ | C18: Angelica | D18: Oncosts | E18: 50021 | F18: Oncosts | H18: 5.66
A19: 43222 | B19: LOPEZ | C19: Angelica | D19: Subsidies | E19: 50016 | F19: Super | H19: 43.01
A20: 43236
A21: 43236 | B21: LOPEZ | C21: Angelica | D21: Earnings | E21: 50002 | F21: Rate O - Marking | G21: 22.5 | H21: 1215.87
A22: 43236 | B22: LOPEZ | C22: Angelica | D22: Oncosts | E22: 50018 | F22: Oncosts | H22: 83.29
A23: 43236 | B23: LOPEZ | C23: Angelica | D23: Oncosts | E23: 50020 | F23: Oncosts | H23: 7.91
A24: 43236 | B24: LOPEZ | C24: Angelica | D24: Oncosts | E24: 50021 | F24: Oncosts | H24: 15.19
A25: 43236 | B25: LOPEZ | C25: Angelica | D25: Subsidies | E25: 50016 | F25: Super | H25: 115.51
A26: 43250
A27: 43250 | B27: LOPEZ | C27: Angelica | D27: Earnings | E27: 50002 | F27: Rate O - Marking | G27: -22.5 | H27: -1215.87
A28: 43250 | B28: LOPEZ | C28: Angelica | D28: Earnings | E28: 50002 | F28: Rate P - Other | G28: 52.5 | H28: 2377.15
A29: 43250 | B29: LOPEZ | C29: Angelica | D29: Earnings | E29: 50002 | F29: Rate Q - Other | G29: 25 | H29: 1350.96
A30: 43250 | B30: LOPEZ | C30: Angelica | D30: Oncosts | E30: 50018 | F30: Oncosts | H30: 172.08
A31: 43250 | B31: LOPEZ | C31: Angelica | D31: Oncosts | E31: 50020 | F31: Oncosts | H31: 17.82
A32: 43250 | B32: LOPEZ | C32: Angelica | D32: Oncosts | E32: 50021 | F32: Oncosts | H32: 31.4
A33: 43250 | B33: LOPEZ | C33: Angelica | D33: Subsidies | E33: 50016 | F33: Super | H33: 260.17
A34: 43264
A35: 43264 | B35: LOPEZ | C35: Angelica | D35: Earnings | E35: 50002 | F35: Rate P - Other | G35: 30 | H35: 1358.37
A36: 43264 | B36: LOPEZ | C36: Angelica | D36: Oncosts | E36: 50018 | F36: Oncosts | H36: 93.04
A37: 43264 | B37: LOPEZ | C37: Angelica | D37: Oncosts | E37: 50020 | F37: Oncosts | H37: 8.84
A38: 43264 | B38: LOPEZ | C38: Angelica | D38: Oncosts | E38: 50021 | F38: Oncosts | H38: 16.98
A39: 43264 | B39: LOPEZ | C39: Angelica | D39: Subsidies | E39: 50016 | F39: Super | H39: 129.05
A40: 43278
...

Sheet Marg_hist
A1: Period End Date | B1: Surname | C1: Preferred Name | D1: GL Record Type Description | E1: Account Number Prefix | F1: Paycode | G1: Salary Hours | H1: Amt$
A2: 43180
A3: 43180 | B3: MEDINA | C3: Margarita | D3: Earnings | E3: 50002 | F3: Rate P - Other | G3: 5 | H3: 226.4
A4: 43180 | B4: MEDINA | C4: Margarita | D4: Oncosts | E4: 50018 | F4: Oncosts | H4: 15.51
A5: 43180 | B5: MEDINA | C5: Margarita | D5: Oncosts | E5: 50020 | F5: Oncosts | H5: 1.47
A6: 43180 | B6: MEDINA | C6: Margarita | D6: Oncosts | E6: 50021 | F6: Oncosts | H6: 2.83
A7: 43180 | B7: MEDINA | C7: Margarita | D7: Subsidies | E7: 50016 | F7: Super | H7: 21.51
A8: 43194
A9: 43194 | B9: MEDINA | C9: Margarita | D9: Earnings | E9: 50002 | F9: Rate P - Other | G9: 5 | H9: 226.4
A10: 43194 | B10: MEDINA | C10: Margarita | D10: Oncosts | E10: 50018 | F10: Oncosts | H10: 15.51
A11: 43194 | B11: MEDINA | C11: Margarita | D11: Oncosts | E11: 50020 | F11: Oncosts | H11: 1.47
A12: 43194 | B12: MEDINA | C12: Margarita | D12: Oncosts | E12: 50021 | F12: Oncosts | H12: 2.83
A13: 43194 | B13: MEDINA | C13: Margarita | D13: Subsidies | E13: 50016 | F13: Super | H13: 21.51
A14: 43222
A15: 43222 | B15: MEDINA | C15: Margarita | D15: Earnings | E15: 50002 | F15: Rate P - Other | G15: 18 | H15: 815.01
A16: 43222 | B16: MEDINA | C16: Margarita | D16: Oncosts | E16: 50018 | F16: Oncosts | H16: 55.83
A17: 43222 | B17: MEDINA | C17: Margarita | D17: Oncosts | E17: 50020 | F17: Oncosts | H17: 5.31
A18: 43222 | B18: MEDINA | C18: Margarita | D18: Oncosts | E18: 50021 | F18: Oncosts | H18: 10.19
A19: 43222 | B19: MEDINA | C19: Margarita | D19: Subsidies | E19: 50016 | F19: Super | H19: 77.43
A20: 43236
A21: 43236 | B21: MEDINA | C21: Margarita | D21: Earnings | E21: 50002 | F21: Rate P - Other | G21: 10 | H21: 452.79
A22: 43236 | B22: MEDINA | C22: Margarita | D22: Oncosts | E22: 50018 | F22: Oncosts | H22: 31.02
A23: 43236 | B23: MEDINA | C23: Margarita | D23: Oncosts | E23: 50020 | F23: Oncosts | H23: 2.95
A24: 43236 | B24: MEDINA | C24: Margarita | D24: Oncosts | E24: 50021 | F24: Oncosts | H24: 5.66
A25: 43236 | B25: MEDINA | C25: Margarita | D25: Subsidies | E25: 50016 | F25: Super | H25: 43.02
A26: 43250
A27: 43250 | B27: MEDINA | C27: Margarita | D27: Earnings | E27: 50002 | F27: Rate P - Other | G27: 14 | H27: 633.91
A28: 43250 | B28: MEDINA | C28: Margarita | D28: Oncosts | E28: 50018 | F28: Oncosts | H28: 43.42
A29: 43250 | B29: MEDINA | C29: Margarita | D29: Oncosts | E29: 50020 | F29: Oncosts | H29: 4.14
A30: 43250 | B30: MEDINA | C30: Margarita | D30: Oncosts | E30: 50021 | F30: Oncosts | H30: 7.92
A31: 43250 | B31: MEDINA | C31: Margarita | D31: Subsidies | E31: 50016 | F31: Super | H31: 60.22
A32: 43264
A33: 43264 | B33: MEDINA | C33: Margarita | D33: Earnings | E33: 50002 | F33: Rate P - Other | G33: 14 | H33: 633.91
A34: 43264 | B34: MEDINA | C34: Margarita | D34: Oncosts | E34: 50018 | F34: Oncosts | H34: 43.42
A35: 43264 | B35: MEDINA | C35: Margarita | D35: Oncosts | E35: 50020 | F35: Oncosts | H35: 4.13
A36: 43264 | B36: MEDINA | C36: Margarita | D36: Oncosts | E36: 50021 | F36: Oncosts | H36: 7.92
A37: 43264 | B37: MEDINA | C37: Margarita | D37: Subsidies | E37: 50016 | F37: Super | H37: 60.22
A38: 43278
A39: 43278 | B39: MEDINA | C39: Margarita | D39: Earnings | E39: 50002 | F39: Rate P - Other | G39: 14 | H39: 633.91
A40: 43278 | B40: MEDINA | C40: Margarita | D40: Oncosts | E40: 50018 | F40: Oncosts | H40: 43.42
...

Sheet Kyle_hist
A1: Period End Date | B1: Surname | C1: Preferred Name | D1: GL Record Type Description | E1: Account Number Prefix | F1: Paycode | G1: Salary Hours | H1: Amt$
A2: 43124
A3: 43124 | B3: HEMMING | C3: Kyle | D3: Earnings | E3: 50007 | F3: Salary Casual | G3: 6.5 | H3: 376.58
A4: 43124 | B4: HEMMING | C4: Kyle | D4: Oncosts | E4: 50031 | F4: Oncosts | H4: 25.8
A5: 43124 | B5: HEMMING | C5: Kyle | D5: Oncosts | E5: 50033 | F5: Oncosts | H5: 4.71
A6: 43138
A7: 43138 | B7: HEMMING | C7: Kyle | D7: Earnings | E7: 50007 | F7: Salary Casual | G7: 21.5 | H7: 1245.59
A8: 43138 | B8: HEMMING | C8: Kyle | D8: Oncosts | E8: 50031 | F8: Oncosts | H8: 85.33
A9: 43138 | B9: HEMMING | C9: Kyle | D9: Oncosts | E9: 50032 | F9: Oncosts | H9: 8.11
A10: 43138 | B10: HEMMING | C10: Kyle | D10: Oncosts | E10: 50033 | F10: Oncosts | H10: 15.57
A11: 43138 | B11: HEMMING | C11: Kyle | D11: Subsidies | E11: 50027 | F11: Super | H11: 118.33
A12: 43166
A13: 43166 | B13: HEMMING | C13: Kyle | D13: Earnings | E13: 50007 | F13: Salary Casual | G13: 6 | H13: 347.61
A14: 43166 | B14: HEMMING | C14: Kyle | D14: Oncosts | E14: 50031 | F14: Oncosts | H14: 23.82
A15: 43166 | B15: HEMMING | C15: Kyle | D15: Oncosts | E15: 50033 | F15: Oncosts | H15: 4.35
A16: 43180
A17: 43180 | B17: HEMMING | C17: Kyle | D17: Earnings | E17: 50007 | F17: Salary Casual | G17: 4 | H17: 231.74
A18: 43180 | B18: HEMMING | C18: Kyle | D18: Oncosts | E18: 50031 | F18: Oncosts | H18: 15.88
A19: 43180 | B19: HEMMING | C19: Kyle | D19: Oncosts | E19: 50032 | F19: Oncosts | H19: 3.77
A20: 43180 | B20: HEMMING | C20: Kyle | D20: Oncosts | E20: 50033 | F20: Oncosts | H20: 2.9
A21: 43180 | B21: HEMMING | C21: Kyle | D21: Subsidies | E21: 50027 | F21: Super | H21: 55.04
A22: 43194
A23: 43194 | B23: HEMMING | C23: Kyle | D23: Earnings | E23: 50007 | F23: Salary Casual | G23: 5 | H23: 289.67
A24: 43194 | B24: HEMMING | C24: Kyle | D24: Oncosts | E24: 50031 | F24: Oncosts | H24: 19.85
A25: 43194 | B25: HEMMING | C25: Kyle | D25: Oncosts | E25: 50032 | F25: Oncosts | H25: 0
A26: 43194 | B26: HEMMING | C26: Kyle | D26: Oncosts | E26: 50033 | F26: Oncosts | H26: 3.62
A27: 43194 | B27: HEMMING | C27: Kyle | D27: Subsidies | E27: 50027 | F27: Super | H27: 0
A28: 43208
A29: 43208 | B29: HEMMING | C29: Kyle | D29: Oncosts | E29: 50032 | F29: Oncosts | H29: 0
A30: 43208 | B30: HEMMING | C30: Kyle | D30: Subsidies | E30: 50027 | F30: Super | H30: 0
A31: 43222
A32: 43222 | B32: HEMMING | C32: Kyle | D32: Oncosts | E32: 50032 | F32: Oncosts | H32: 0
A33: 43222 | B33: HEMMING | C33: Kyle | D33: Subsidies | E33: 50027 | F33: Super | H33: 0
A34: 43222 | B34: HEMMING | C34: Kyle | D34: Earnings | E34: 50002 | F34: Rate P - Other | G34: 40 | H34: 1811.16
A35: 43222 | B35: HEMMING | C35: Kyle | D35: Oncosts | E35: 50018 | F35: Oncosts | H35: 124.05
A36: 43222 | B36: HEMMING | C36: Kyle | D36: Oncosts | E36: 50020 | F36: Oncosts | H36: 11.79
A37: 43222 | B37: HEMMING | C37: Kyle | D37: Oncosts | E37: 50021 | F37: Oncosts | H37: 22.64
A38: 43222 | B38: HEMMING | C38: Kyle | D38: Subsidies | E38: 50016 | F38: Super | H38: 172.06
A39: 43236
A40: 43236 | B40: HEMMING | C40: Kyle | D40: Oncosts | E40: 50032 | F40: Oncosts | H40: 0
...

Sheet Angelica
A1: Angelica Lopez
B5: Week of 26/02/2018 | C5: Start | D5: Finish | E5: Hrs worked | F5: Total Pay | G5: Description
B6: Monday
B7: Tuesday
B8: Wednesday
B9: Thursday | C9: 0.54166667 | D9: 0.625 | E9: 2
B10: Friday | C10: 0.54166667 | D10: 0.625 | E10: 2
B11: Saturday
B12: Sunday
B16: Week of 05/03/2018 | C16: Start | D16: Finish | E16: Hrs worked | F16: Total Pay | G16: Description
B17: Monday
B18: Tuesday
B19: Wednesday | E19: 3
B20: Thursday | C20: 0.39583333 | D20: 0.45833333 | E20: 1.5
C21: 0.54166667 | D21: 0.625 | E21: 2
B22: Friday
B23: Saturday
B24: Sunday
E25: =SUM(E9:E10,E19:E21) -> 10.5
A27: before this point all work was PAID IN VOUCHERS…
B29: ANTHONY's INPUT | J29: ANGELICA's RECORDED HOURS
L33: Week of 12/03/2018
B34: Week of 12/03/2018 | C34: Start | D34: Finish | E34: Hrs worked | F34: Hrs Paid | G34: Description | H34: Payment received | K34: W5 | L34: Week of 12/03/2018 | M34: Start | N34: Finish | O34: Hrs worked | P34: Payment received
A35: 12 | B35: Monday | K35: 12 | L35: Monday
A36: 13 | B36: Tuesday | C36: 0.375 | D36: 0.5 | E36: 3 | G36: Seaching by courses using different terminology to list the list of statistical courses offered at UC. The whole dataset is complete it | K36: 13 | L36: Tuesday | M36: 0.375 | N36: 0.95833333 | O36: 2 | Q36: Seaching by courses using different terminology to list the list of statistical courses offered at UC. The whole dataset is complete it
A37: 14 | B37: Wednesday | K37: 14 | L37: Wednesday
A38: 15 | B38: Thursday | C38: 0.54166667 | D38: 0.625 | E38: 2 | G38: Regular Drop in | K38: 15 | L38: Thursday | M38: 0.54166667 | N38: 0.125 | O38: 2 | Q38: Regular Drop in
A39: 16 | B39: Friday | C39: 0.375 | D39: 0.5 | E39: 3 | G39: organized files. In dropbox. Reading and organized the whole files and build a dataset of files. | K39: 16 | L39: Friday | M39: 0.375 | N39: 0.95833333 | O39: 2 | P39: 5 | Q39: organized files. In dropbox. Reading and organized the whole files and build a dataset of files. Check face history for discussion
A40: 17 | B40: Saturday | K40: 17 | L40: Saturday
A41: 18 | B41: Sunday | K41: 18 | L41: Sunday
B42: TOTAL | E42: =SUM(E35:E41) -> 8 | F42: Hours submitted | G42: Hours owing
A43: Tuesday 21 March | B43: Payday | E43: =SUM(E35:E39) -> 8 | F43: =SUM(1*Angelica_hist!G3) -> 5 | G43: =SUM(E43-F43) -> 3
B46: Week of 19/03/2018 | C46: Start | D46: Finish | E46: Hrs worked | F46: Hrs Paid | G46: Description | H46: Payment received | K46: W6 | L46: Week of 19/03/2018 | M46: Start | N46: Finish | O46: Hrs worked
A47: 19 | B47: Monday | K47: 19 | L47: Monday
A48: 20 | B48: Tuesday | K48: 20 | L48: Tuesday
A49: 21 | B49: Wednesday | K49: 21 | L49: Wednesday
A50: 22 | B50: Thursday | C50: 0.54166667 | D50: 0.625 | E50: 2 | G50: Regular Drop in | K50: 22 | L50: Thursday | M50: 0.54166667 | N50: 0.125 | O50: 2 | Q50: Regular Drop in
A51: 23 | B51: Friday | C51: 0.375 | D51: 0.45833333 | E51: 2 | G51: Statistical Network project process and possible tasks. In dropbox. | K51: 23 | L51: Friday | M51: 0.375 | N51: 0.45833333 | O51: 2 | P51: 5 | Q51: organized files. In dropbox. Reading and organized the whole files and build a dataset of files.
A52: 24 | B52: Saturday | K52: 24 | L52: Saturday
A53: 25 | B53: Sunday | K53: 25 | L53: Sunday
...

Sheet Margarita
A1: Margarita | B1: ANTHONY's INPUT
A2: NEW CONTRACT
A4: END CONTRACT START A NEW ONE | B4: Week of 05/03/2018 | C4: Start | D4: Finish | E4: Hrs worked | F4: Total Pay | G4: Description | I4: Stage one | J4: 1st February - 13th May | O4: Week of 05/03/2018 | P4: Start | Q4: Finish | R4: Hrs worked | S4: Total Pay | T4: Description
A5: 4 | B5: Monday | C5: 0.625 | D5: 0.66666667 | E5: 1 | G5: Asking about job situation and lining up timetables | I5: Stage two | J5: 14th May - 1 July | O5: Monday | P5: 0.625 | Q5: 0.66666667 | R5: 1 | T5: Asking about job situation and lining up timetables
A6: 5 | B6: Tuesday | I6: Stage three: Current | J6: 2 July 2018 - 1st September 2018 | O6: Tuesday
A7: 6 | B7: Wednesday | C7: 0.625 | D7: 0.66666667 | E7: 1 | G7: Meeting for contracts etc | O7: Wednesday | P7: 0.625 | Q7: 0.66666667 | R7: 1 | T7: Meeting for contracts etc
A8: 7 | B8: Thursday | O8: Thursday
A9: 8 | O9: Friday
A10: 9 | B10: Friday | O10: Saturday
A11: 10 | B11: Saturday | O11: Sunday
A12: 11 | B12: Sunday | O12: TOTAL | R12: =SUM(R5:R11) -> 2
B13: TOTAL | E13: =SUM(E5:E12) -> 2
B15: Week of 12/03/2018 | C15: Start | D15: Finish | E15: Hrs worked | F15: Hrs Paid | G15: Description | H15: Payment received | O15: Week of 12/03/2018 | P15: Start | Q15: Finish | R15: Hrs worked | S15: Total Pay | T15: Description
A16: 12 | B16: Monday | O16: Monday
A17: 13 | B17: Tuesday | O17: Tuesday
A18: 14 | B18: Wednesday | O18: Wednesday
A19: 15 | B19: Thursday | O19: Thursday
A20: 16 | B20: Friday | O20: Friday
A21: 17 | B21: Saturday | O21: Saturday
A22: 18 | B22: Sunday | O22: Sunday
B23: TOTAL | E23: =SUM(E16:E22) -> 0 | F23: Hours submitted | G23: Hours owing | O23: TOTAL
A24: Tuesday 21 March | B24: Payday | E24: =SUM(E23+E13) -> 2 | F24: =SUM(1*Marg_hist!G3) -> 5 | G24: =SUM(E24+G13)-F24 -> -3
B27: Week of 19/03/2018 | C27: Start | D27: Finish | E27: Hrs worked | F27: Hrs Paid | G27: Description | H27: Payment received | O27: Week of 19/03/2018 | P27: Start | Q27: Finish | R27: Hrs worked | S27: Total Pay | T27: Description
A28: 19 | B28: Monday | O28: Monday
A29: 20 | B29: Tuesday | O29: Tuesday
A30: 21 | B30: Wednesday | O30: Wednesday
A31: 22 | B31: Thursday | O31: Thursday
A32: 23 | B32: Friday | O32: Friday
A33: 24 | B33: Saturday | O33: Saturday
A34: 25 | B34: Sunday | O34: Sunday
B35: TOTAL | E35: =SUM(E27:E34) -> 0 | O35: TOTAL
O36: PAID | R36: 8hrs owing | S36: 10hrs paid
B37: Week of 26/03/2018 | C37: Start | D37: Finish | E37: Hrs worked | F37: Total Pay | G37: Description | O37: Week of 26/03/2018 | P37: Start | Q37: Finish | R37: Hrs worked | S37: Total Pay | T37: Description
A38: 26 | B38: Monday | O38: Monday
A39: 27 | B39: Tuesday | O39: Tuesday
A40: 28 | B40: Wednesday 28 march | O40: Wednesday
A41: 29 | B41: Thursday | C41: 0.5 | D41: 0.66666667 | E41: 4 | G41: Meeting / admin / emails | O41: Thursday | P41: 0.5 | Q41: 0.66666667 | R41: 4 | T41: Meeting / admin / emails
A42: 30 | B42: Friday | O42: Friday
A43: 31 | B43: Saturday | O43: Saturday
A44: 1 | B44: Sunday | O44: Sunday
...

Sheet Margarita (2)
A1: Margarita
A8: ANTHONY's INPUT
A9: NEW CONTRACT
A11: END CONTRACT START A NEW ONE | B11: Week of 05/03/2018 | C11: Start | D11: Finish | E11: Hrs worked | F11: Total Pay | G11: Description | I11: Stage one | J11: 1st February - 13th May
A12: 4 | B12: Monday | C12: 0.625 | D12: 0.66666667 | E12: 1 | G12: Asking about job situation and lining up timetables | I12: Stage two | J12: 14th May - 1 July
A13: 5 | B13: Tuesday | I13: Stage three: Current | J13: 2 July 2018 - 1st September 2018
A14: 6 | B14: Wednesday | C14: 0.625 | D14: 0.66666667 | E14: 1 | G14: Meeting for contracts etc
A15: 7 | B15: Thursday
A16: 8
A17: 9 | B17: Friday
A18: 10 | B18: Saturday
A19: 11 | B19: Sunday
B20: TOTAL | E20: =SUM(E12:E19) -> 2
B22: Week of 12/03/2018 | C22: Start | D22: Finish | E22: Hrs worked | F22: Hrs Paid | G22: Description | H22: Payment received
A23: 12 | B23: Monday
A24: 13 | B24: Tuesday
A25: 14 | B25: Wednesday
A26: 15 | B26: Thursday
A27: 16 | B27: Friday
A28: 17 | B28: Saturday
A29: 18 | B29: Sunday
B30: TOTAL | E30: =SUM(E23:E29) -> 0 | F30: Hours submitted | G30: Hours owing
A31: Tuesday 21 March | B31: Payday | E31: =SUM(E30+E20) -> 2 | F31: =SUM(1*[3]Marg_hist!G3) -> 5 | G31: =SUM(E31+G20)-F31 -> -3
A32: 43180
B34: Week of 19/03/2018 | C34: Start | D34: Finish | E34: Hrs worked | F34: Hrs Paid | G34: Description | H34: Payment received
A35: 19 | B35: Monday
A36: 20 | B36: Tuesday
A37: 21 | B37: Wednesday
A38: 22 | B38: Thursday
A39: 23 | B39: Friday
A40: 24 | B40: Saturday
A41: 25 | B41: Sunday
B42: TOTAL | E42: =SUM(E34:E41) -> 0
B44: Week of 26/03/2018 | C44: Start | D44: Finish | E44: Hrs worked | F44: Total Pay | G44: Description
A45: 26 | B45: Monday
A46: 27 | B46: Tuesday
A47: 28 | B47: Wednesday 28 march
A48: 29 | B48: Thursday | C48: 0.5 | D48: 0.66666667 | E48: 4 | G48: Meeting / admin / emails
A49: 30 | B49: Friday
A50: 31 | B50: Saturday
...

Sheet Kyle
A1: Kyle Hemming
A2: Weekly roster | L2: Stock take 17/07/2018
B3: Start | C3: Finish | D3: Hrs worked | E3: Total Pay | F3: Description | M3: Hrs Paid | N3: Estimated pay | O3: Cash received | P3: Difference | Q3: Description
A4: Monday | G4: Kyle has been doing the drop-in sessions from the very beginning of the statistics network in 2017. There has been mininal variation in the timesheets or workload other than during transistion periods. | L4: Trial
A5: Tuesday | L5: 2months
A6: Wednesday | L6: 6months
A7: Thursday | B7: 0.54166667 | C7: 0.125 | D7: 2 | F7: Drop-in session | L7: July….
A8: Friday
A9: Saturday
A10: Sunday
A11: TOTAL | D11: 2
A14: Submit paper forms | B14: Submit electronic | C14: Payday | D14: Hrs worked | E14: Hrs submitted | F14: Hrs paid
A15: Previous trial period……
C18: 11th January 2018 | D18: 4
C19: 25th January 2018 | D19: 4 | E19: =SUM(Kyle_hist!G3) -> 6.5
C20: 8th February 2018 | D20: 4 | E20: =SUM(Kyle_hist!G7) -> 21.5 | G20: Back pay
C21: 22nd February 2018 | D21: 4
C22: 8th March 2018 | D22: 4 | E22: =SUM(Kyle_hist!G13) -> 6
C23: 22nd March 2018 | D23: 4 | E23: =SUM(Kyle_hist!G17) -> 4
C24: 5th April 2018 | D24: 4 | E24: =SUM(Kyle_hist!G23) -> 5
C25: 19th April 2018 | D25: 4 | E25: =SUM(Kyle_hist!G9) -> 0
C26: 3rd May 2018 | D26: 4 | E26: =SUM(Kyle_hist!G34) -> 40 | G26: Pay screw-up
C27: 17th May 2018 | D27: 2 | E27: =SUM(Kyle_hist!G42) -> -19 | G27: Pay screw-up
C28: 31st May 2018 | D28: 4 | E28: =SUM(Kyle_hist!G50) -> 4
C29: 14th June 2018 | D29: 4 | E29: =SUM(Kyle_hist!G56) -> 4
C30: 27th June 2018 | D30: 4 | E30: =SUM(Kyle_hist!G60) -> 4
C31: 11th July 2018 | D31: 4 | E31: =SUM(Kyle_hist!G64) -> 7 | G31: Shut-up and write too…??
C32: 26th July 2018
C33: 9th August 2018
C34: 23rd August 2018
C35: 6th September 2018
C36: 20th September 2018
C37: 4th October 2018
C38: 18th October 2018
C39: 1st November 2018
C40: 15th Novermber 2018
C41: 29th November 2018
C42: 13th December 2018
C43: 27th December 2018
A44: TOTALS | C44: TOTAL | E44: =SUM(E18:E43) -> 83
...

Sheet Draft_timesheet
A1: Overall timesheet | H1: Stage | I1: Time | J1: Status | K1: Due date
A2: For the next set of Acidemic contracts: Stage three (July 2018 - September 2018) | H2: Stage one | I2: 1st February - 13th May | J2: DONE
H3: Stage two | I3: 14th May - 1 July | J3: DONE
H4: Stage three | I4: 2 July 2018 - 1st September 2018 | J4: CURRENT | K4: 31st July 2018
H5: Stage four | I5: 2nd September 2018 - 31st December 2018 | J5: DRAFT NEEDED | K5: 28th August 2018
A9: 23-29 July 2018 | B9: WS=W1 | C9: Monday | D9: Tuesday | E9: Wednesday | F9: Thursday | G9: Friday | H9: Saturday | I9: Sunday | J9: Total
B10: Anthony | D10: 4 | G10: 4 | J10: =SUM(C10:I10) -> 8 | K10: NOTE: Must have timesheet to be pay this by Monday 30th
C11: 9am - 5pm office (3C3)
B12: Margarita | C12: 0 | D12: 0 | E12: RDO | F12: 7 | G12: 0 | J12: =SUM(C12:I12) -> 7
C13: One-on-one | F13: 9am - 4.30pm (30min break) | G13: One-on-one
B14: Angelica | C14: RDO | D14: RDO | E14: RDO | F14: RDO | G14: RDO | H14: 5hrs over weekend or evenings with previous researchers | I14: 5 | J14: =SUM(C14:I14) -> 5
B16: Kyle | C16: RDO | D16: RDO | E16: RDO | F16: 2 | G16: RDO | J16: =SUM(C16:I16) -> 2
F17: Drop-in session
B18: Researcher development
B19: Total | C19: 2 | D19: 4 | E19: 2 | F19: 7 | G19: 4 | J19: =SUM(J10:J18) -> 22
A22: 30 July-5 August 2018 | B22: WS=W2 | C22: Monday | D22: Tuesday | E22: Wednesday | F22: Thursday | G22: Friday | H22: Saturday | I22: Sunday | J22: Total
B23: Anthony | D23: 4 | G23: 4 | J23: =SUM(C23:I23) -> 8 | K23: NOTE: Must have timesheet to be pay this by Monday 6th
C24: 9am - 5pm office (3C3)
B25: Margarita | C25: 2 | D25: 0 | E25: RDO | F25: 7 | G25: 2 | J25: =SUM(C25:I25) -> 11
C26: One-on-one | F26: 9am - 4.30pm (30min break) | G26: One-on-one
B27: Angelica | C27: RDO | D27: RDO | E27: RDO | F27: RDO | G27: RDO | H27: 2hrs over weekend or evenings with previous researchers | J27: 2
B29: New Staff 1 | F29: 2 | J29: 2
F30: Drop-in session
B31: Kyle | C31: RDO | D31: RDO | E31: RDO | F31: 2 | G31: RDO | J31: =SUM(C31:I31) -> 2
F32: Drop-in session
B33: Researcher development | J33: =SUM(C32:I32) -> 0
B34: Total | C34: 2 | D34: 4 | E34: 2 | F34: 7 | G34: 4 | J34: =SUM(J23:J33) -> 25
A37: 6-12 August 2018 | B37: WS=W3 | C37: Monday | D37: Tuesday | E37: Wednesday | F37: Thursday | G37: Friday | H37: Saturday | I37: Sunday | J37: Total
B38: Anthony | D38: 4 | G38: 4 | J38: =SUM(C38:I38) -> 8 | K38: NOTE: Must have timesheet to be pay this by Monday 13th
C39: 9am - 5pm office (3C3)
B40: Margarita | C40: 2 | D40: 4 | E40: RDO | F40: 7 | G40: 2 | J40: =SUM(C40:I40) -> 15
C41: One-on-one | F41: 9am - 4.30pm (30min break) | G41: One-on-one
B42: New Staff 1 | C42: RDO | D42: RDO | E42: RDO | F42: 2 | G42: RDO | H42: Over weekend or evenings as needed | J42: =SUM(C42:I42) -> 2
F43: Drop-in session
B44: Kyle | C44: RDO | D44: RDO | E44: RDO | F44: 2 | G44: RDO | J44: =SUM(C44:I44) -> 2
F45: Drop-in session
B46: Researcher development | J46: =SUM(C45:I45) -> 0
B47: Total | C47: 2 | D47: 4 | E47: 2 | F47: 7 | G47: 4 | J47: =SUM(J38:J46) -> 27
A50: 13-19 August 2018 | B50: WS=W4 | C50: Monday | D50: Tuesday | E50: Wednesday | F50: Thursday | G50: Friday | H50: Saturday | I50: Sunday | J50: Total
B51: Anthony | D51: 4 | G51: 4 | J51: =SUM(C51:I51) -> 8 | K51: NOTE: Must have timesheet to be pay this by Monday 20th
...

Sheet Dates

Sheet 2 CostByEmployee_Data
B2: Report by Cost Centre - All Employees including Casuals/ Sessionals
C4: Includes Earning, Oncosts and Super ('Subsidies'). Excludes Deductions
C6: Period End Date | D6: School | E6: Cost Centre Code | F6: Project Code | G6: Emp. No. | H6: Surname | I6: Preferred Name | J6: Highest Classification | K6: Job Number | L6: Position Title | M6: GL Record Type Description | N6: Account Number Prefix | O6: Paycode | P6: Salary Hours | Q6: Amt$
C7: 43124 | D7: Graduate Research | E7: 6283 | G7: 435389 | H7: DAVIDSON | I7: Anthony | K7: 02 | M7: Earnings | N7: 50007 | O7: Salary Casual | P7: 12.5 | Q7: 716.91
C8: 43124 | D8: Graduate Research | E8: 6283 | G8: 435389 | H8: DAVIDSON | I8: Anthony | K8: 02 | M8: Oncosts | N8: 50031 | O8: Oncosts | Q8: 49.11
C9: 43124 | D9: Graduate Research | E9: 6283 | G9: 435389 | H9: DAVIDSON | I9: Anthony | K9: 02 | M9: Oncosts | N9: 50032 | O9: Oncosts | Q9: 4.67
C10: 43124 | D10: Graduate Research | E10: 6283 | G10: 435389 | H10: DAVIDSON | I10: Anthony | K10: 02 | M10: Oncosts | N10: 50033 | O10: Oncosts | Q10: 8.95
C11: 43124 | D11: Graduate Research | E11: 6283 | G11: 435389 | H11: DAVIDSON | I11: Anthony | K11: 02 | M11: Subsidies | N11: 50027 | O11: Super | Q11: 68.11
C12: 43124 | D12: Graduate Research | E12: 6283 | G12: 436862 | H12: HEMMING | I12: Kyle | K12: 02 | M12: Earnings | N12: 50007 | O12: Salary Casual | P12: 6.5 | Q12: 376.58
C13: 43124 | D13: Graduate Research | E13: 6283 | G13: 436862 | H13: HEMMING | I13: Kyle | K13: 02 | M13: Oncosts | N13: 50031 | O13: Oncosts | Q13: 25.8
C14: 43124 | D14: Graduate Research | E14: 6283 | G14: 436862 | H14: HEMMING | I14: Kyle | K14: 02 | M14: Oncosts | N14: 50033 | O14: Oncosts | Q14: 4.71
C15: 43138 | D15: Graduate Research | E15: 6283 | G15: 435389 | H15: DAVIDSON | I15: Anthony | K15: 02 | M15: Earnings | N15: 50007 | O15: Salary Casual | P15: 73.5 | Q15: 4258.2
C16: 43138 | D16: Graduate Research | E16: 6283 | G16: 435389 | H16: DAVIDSON | I16: Anthony | K16: 02 | M16: Oncosts | N16: 50031 | O16: Oncosts | Q16: 291.7
C17: 43138 | D17: Graduate Research | E17: 6283 | G17: 435389 | H17: DAVIDSON | I17: Anthony | K17: 02 | M17: Oncosts | N17: 50032 | O17: Oncosts | Q17: 27.71
C18: 43138 | D18: Graduate Research | E18: 6283 | G18: 435389 | H18: DAVIDSON | I18: Anthony | K18: 02 | M18: Oncosts | N18: 50033 | O18: Oncosts | Q18: 53.22
C19: 43138 | D19: Graduate Research | E19: 6283 | G19: 435389 | H19: DAVIDSON | I19: Anthony | K19: 02 | M19: Subsidies | N19: 50027 | O19: Super | Q19: 404.53
C20: 43138 | D20: Graduate Research | E20: 6283 | G20: 436862 | H20: HEMMING | I20: Kyle | K20: 02 | M20: Earnings | N20: 50007 | O20: Salary Casual | P20: 21.5 | Q20: 1245.59
C21: 43138 | D21: Graduate Research | E21: 6283 | G21: 436862 | H21: HEMMING | I21: Kyle | K21: 02 | M21: Oncosts | N21: 50031 | O21: Oncosts | Q21: 85.33
C22: 43138 | D22: Graduate Research | E22: 6283 | G22: 436862 | H22: HEMMING | I22: Kyle | K22: 02 | M22: Oncosts | N22: 50032 | O22: Oncosts | Q22: 8.11
C23: 43138 | D23: Graduate Research | E23: 6283 | G23: 436862 | H23: HEMMING | I23: Kyle | K23: 02 | M23: Oncosts | N23: 50033 | O23: Oncosts | Q23: 15.57
C24: 43138 | D24: Graduate Research | E24: 6283 | G24: 436862 | H24: HEMMING | I24: Kyle | K24: 02 | M24: Subsidies | N24: 50027 | O24: Super | Q24: 118.33
C25: 43166 | D25: Graduate Research | E25: 6283 | G25: 432401 | H25: GALVIN | I25: Catherine | K25: 03 | M25: Earnings | N25: 50002 | O25: Rate B - Lecturing | P25: 6 | Q25: 1517.08
C26: 43166 | D26: Graduate Research | E26: 6283 | G26: 432401 | H26: GALVIN | I26: Catherine | K26: 03 | M26: Oncosts | N26: 50018 | O26: Oncosts | Q26: 103.92
C27: 43166 | D27: Graduate Research | E27: 6283 | G27: 432401 | H27: GALVIN | I27: Catherine | K27: 03 | M27: Oncosts | N27: 50020 | O27: Oncosts | Q27: 9.87
C28: 43166 | D28: Graduate Research | E28: 6283 | G28: 432401 | H28: GALVIN | I28: Catherine | K28: 03 | M28: Oncosts | N28: 50021 | O28: Oncosts | Q28: 18.96
C29: 43166 | D29: Graduate Research | E29: 6283 | G29: 432401 | H29: GALVIN | I29: Catherine | K29: 03 | M29: Subsidies | N29: 50016 | O29: Super | Q29: 144.12
C30: 43166 | D30: Graduate Research | E30: 6283 | G30: 435389 | H30: DAVIDSON | I30: Anthony | K30: 02 | M30: Earnings | N30: 50007 | O30: Salary Casual | P30: 6 | Q30: 347.6
C31: 43166 | D31: Graduate Research | E31: 6283 | G31: 435389 | H31: DAVIDSON | I31: Anthony | K31: 02 | M31: Oncosts | N31: 50031 | O31: Oncosts | Q31: 23.81
C32: 43166 | D32: Graduate Research | E32: 6283 | G32: 435389 | H32: DAVIDSON | I32: Anthony | K32: 02 | M32: Oncosts | N32: 50033 | O32: Oncosts | Q32: 4.35
C33: 43166 | D33: Graduate Research | E33: 6283 | G33: 436862 | H33: HEMMING | I33: Kyle | K33: 02 | M33: Earnings | N33: 50007 | O33: Salary Casual | P33: 6 | Q33: 347.61
C34: 43166 | D34: Graduate Research | E34: 6283 | G34: 436862 | H34: HEMMING | I34: Kyle | K34: 02 | M34: Oncosts | N34: 50031 | O34: Oncosts | Q34: 23.82
C35: 43166 | D35: Graduate Research | E35: 6283 | G35: 436862 | H35: HEMMING | I35: Kyle | K35: 02 | M35: Oncosts | N35: 50033 | O35: Oncosts | Q35: 4.35
C36: 43180 | D36: Graduate Research | E36: 6283 | G36: 429372 | H36: LOPEZ | I36: Angelica | K36: 04 | M36: Earnings | N36: 50002 | O36: Rate P - Other | P36: 5 | Q36: 226.4
C37: 43180 | D37: Graduate Research | E37: 6283 | G37: 429372 | H37: LOPEZ | I37: Angelica | K37: 04 | M37: Oncosts | N37: 50018 | O37: Oncosts | Q37: 15.51
C38: 43180 | D38: Graduate Research | E38: 6283 | G38: 429372 | H38: LOPEZ | I38: Angelica | K38: 04 | M38: Oncosts | N38: 50020 | O38: Oncosts | Q38: 1.47
C39: 43180 | D39: Graduate Research | E39: 6283 | G39: 429372 | H39: LOPEZ | I39: Angelica | K39: 04 | M39: Oncosts | N39: 50021 | O39: Oncosts | Q39: 2.83
C40: 43180 | D40: Graduate Research | E40: 6283 | G40: 429372 | H40: LOPEZ | I40: Angelica | K40: 04 | M40: Subsidies | N40: 50016 | O40: Super | Q40: 21.51
C41: 43180 | D41: Graduate Research | E41: 6283 | G41: 430664 | H41: MEDINA | I41: Margarita | K41: 04 | M41: Earnings | N41: 50002 | O41: Rate P - Other | P41: 5 | Q41: 226.4
C42: 43180 | D42: Graduate Research | E42: 6283 | G42: 430664 | H42: MEDINA | I42: Margarita | K42: 04 | M42: Oncosts | N42: 50018 | O42: Oncosts | Q42: 15.51
C43: 43180 | D43: Graduate Research | E43: 6283 | G43: 430664 | H43: MEDINA | I43: Margarita | K43: 04 | M43: Oncosts | N43: 50020 | O43: Oncosts | Q43: 1.47
...

Sheet Extra_earnings
A1: 43166 | B1: Graduate Research | C1: 6283 | E1: 432401 | F1: GALVIN | G1: Catherine | I1: 03 | K1: Earnings | L1: 50002 | M1: Rate B - Lecturing | N1: 6 | O1: 1517.08
A2: 43166 | B2: Graduate Research | C2: 6283 | E2: 432401 | F2: GALVIN | G2: Catherine | I2: 03 | K2: Oncosts | L2: 50018 | M2: Oncosts | O2: 103.92
A3: 43166 | B3: Graduate Research | C3: 6283 | E3: 432401 | F3: GALVIN | G3: Catherine | I3: 03 | K3: Oncosts | L3: 50020 | M3: Oncosts | O3: 9.87
A4: 43166 | B4: Graduate Research | C4: 6283 | E4: 432401 | F4: GALVIN | G4: Catherine | I4: 03 | K4: Oncosts | L4: 50021 | M4: Oncosts | O4: 18.96
A5: 43166 | B5: Graduate Research | C5: 6283 | E5: 432401 | F5: GALVIN | G5: Catherine | I5: 03 | K5: Subsidies | L5: 50016 | M5: Super | O5: 144.12
A6: 43250 | B6: Graduate Research | C6: 6283 | E6: 432401 | F6: GALVIN | G6: Catherine | I6: 03 | K6: Oncosts | L6: 50020 | M6: Oncosts | O6: 0
A7: 43250 | B7: Graduate Research | C7: 6283 | E7: 432401 | F7: GALVIN | G7: Catherine | I7: 03 | K7: Subsidies | L7: 50016 | M7: Super | O7: 0

Sheet Removed_extra
A1: Period End Date | B1: Emp. No. | C1: Surname | D1: Preferred Name | E1: Job Number | F1: GL Record Type Description | G1: Account Number Prefix | H1: Paycode | I1: Salary Hours | J1: Amt$
A2: 43124 | B2: 435389 | C2: DAVIDSON | D2: Anthony | E2: 02 | F2: Earnings | G2: 50007 | H2: Salary Casual | I2: 12.5 | J2: 716.91
A3: 43124 | B3: 435389 | C3: DAVIDSON | D3: Anthony | E3: 02 | F3: Oncosts | G3: 50031 | H3: Oncosts | J3: 49.11
A4: 43124 | B4: 435389 | C4: DAVIDSON | D4: Anthony | E4: 02 | F4: Oncosts | G4: 50032 | H4: Oncosts | J4: 4.67
A5: 43124 | B5: 435389 | C5: DAVIDSON | D5: Anthony | E5: 02 | F5: Oncosts | G5: 50033 | H5: Oncosts | J5: 8.95
A6: 43124 | B6: 435389 | C6: DAVIDSON | D6: Anthony | E6: 02 | F6: Subsidies | G6: 50027 | H6: Super | J6: 68.11
A7: 43124 | B7: 436862 | C7: HEMMING | D7: Kyle | E7: 02 | F7: Earnings | G7: 50007 | H7: Salary Casual | I7: 6.5 | J7: 376.58
A8: 43124 | B8: 436862 | C8: HEMMING | D8: Kyle | E8: 02 | F8: Oncosts | G8: 50031 | H8: Oncosts | J8: 25.8
A9: 43124 | B9: 436862 | C9: HEMMING | D9: Kyle | E9: 02 | F9: Oncosts | G9: 50033 | H9: Oncosts | J9: 4.71
A10: 43138 | B10: 435389 | C10: DAVIDSON | D10: Anthony | E10: 02 | F10: Earnings | G10: 50007 | H10: Salary Casual | I10: 73.5 | J10: 4258.2
A11: 43138 | B11: 435389 | C11: DAVIDSON | D11: Anthony | E11: 02 | F11: Oncosts | G11: 50031 | H11: Oncosts | J11: 291.7
A12: 43138 | B12: 435389 | C12: DAVIDSON | D12: Anthony | E12: 02 | F12: Oncosts | G12: 50032 | H12: Oncosts | J12: 27.71
A13: 43138 | B13: 435389 | C13: DAVIDSON | D13: Anthony | E13: 02 | F13: Oncosts | G13: 50033 | H13: Oncosts | J13: 53.22
A14: 43138 | B14: 435389 | C14: DAVIDSON | D14: Anthony | E14: 02 | F14: Subsidies | G14: 50027 | H14: Super | J14: 404.53
A15: 43138 | B15: 436862 | C15: HEMMING | D15: Kyle | E15: 02 | F15: Earnings | G15: 50007 | H15: Salary Casual | I15: 21.5 | J15: 1245.59
A16: 43138 | B16: 436862 | C16: HEMMING | D16: Kyle | E16: 02 | F16: Oncosts | G16: 50031 | H16: Oncosts | J16: 85.33
A17: 43138 | B17: 436862 | C17: HEMMING | D17: Kyle | E17: 02 | F17: Oncosts | G17: 50032 | H17: Oncosts | J17: 8.11
A18: 43138 | B18: 436862 | C18: HEMMING | D18: Kyle | E18: 02 | F18: Oncosts | G18: 50033 | H18: Oncosts | J18: 15.57
A19: 43138 | B19: 436862 | C19: HEMMING | D19: Kyle | E19: 02 | F19: Subsidies | G19: 50027 | H19: Super | J19: 118.33
A20: 43166 | B20: 435389 | C20: DAVIDSON | D20: Anthony | E20: 02 | F20: Earnings | G20: 50007 | H20: Salary Casual | I20: 6 | J20: 347.6
A21: 43166 | B21: 435389 | C21: DAVIDSON | D21: Anthony | E21: 02 | F21: Oncosts | G21: 50031 | H21: Oncosts | J21: 23.81
A22: 43166 | B22: 435389 | C22: DAVIDSON | D22: Anthony | E22: 02 | F22: Oncosts | G22: 50033 | H22: Oncosts | J22: 4.35
A23: 43166 | B23: 436862 | C23: HEMMING | D23: Kyle | E23: 02 | F23: Earnings | G23: 50007 | H23: Salary Casual | I23: 6 | J23: 347.61
A24: 43166 | B24: 436862 | C24: HEMMING | D24: Kyle | E24: 02 | F24: Oncosts | G24: 50031 | H24: Oncosts | J24: 23.82
A25: 43166 | B25: 436862 | C25: HEMMING | D25: Kyle | E25: 02 | F25: Oncosts | G25: 50033 | H25: Oncosts | J25: 4.35
A26: 43180 | B26: 429372 | C26: LOPEZ | D26: Angelica | E26: 04 | F26: Earnings | G26: 50002 | H26: Rate P - Other | I26: 5 | J26: 226.4
A27: 43180 | B27: 429372 | C27: LOPEZ | D27: Angelica | E27: 04 | F27: Oncosts | G27: 50018 | H27: Oncosts | J27: 15.51
A28: 43180 | B28: 429372 | C28: LOPEZ | D28: Angelica | E28: 04 | F28: Oncosts | G28: 50020 | H28: Oncosts | J28: 1.47
A29: 43180 | B29: 429372 | C29: LOPEZ | D29: Angelica | E29: 04 | F29: Oncosts | G29: 50021 | H29: Oncosts | J29: 2.83
A30: 43180 | B30: 429372 | C30: LOPEZ | D30: Angelica | E30: 04 | F30: Subsidies | G30: 50016 | H30: Super | J30: 21.51
A31: 43180 | B31: 435389 | C31: DAVIDSON | D31: Anthony | E31: 02 | F31: Earnings | G31: 50007 | H31: Salary Casual | I31: 1 | J31: 57.93
A32: 43180 | B32: 435389 | C32: DAVIDSON | D32: Anthony | E32: 02 | F32: Oncosts | G32: 50031 | H32: Oncosts | J32: 3.97
A33: 43180 | B33: 435389 | C33: DAVIDSON | D33: Anthony | E33: 02 | F33: Oncosts | G33: 50033 | H33: Oncosts | J33: 0.72
A34: 43180 | B34: 436862 | C34: HEMMING | D34: Kyle | E34: 02 | F34: Earnings | G34: 50007 | H34: Salary Casual | I34: 4 | J34: 231.74
A35: 43180 | B35: 436862 | C35: HEMMING | D35: Kyle | E35: 02 | F35: Oncosts | G35: 50031 | H35: Oncosts | J35: 15.88
A36: 43180 | B36: 436862 | C36: HEMMING | D36: Kyle | E36: 02 | F36: Oncosts | G36: 50032 | H36: Oncosts | J36: 3.77
A37: 43180 | B37: 436862 | C37: HEMMING | D37: Kyle | E37: 02 | F37: Oncosts | G37: 50033 | H37: Oncosts | J37: 2.9
A38: 43180 | B38: 436862 | C38: HEMMING | D38: Kyle | E38: 02 | F38: Subsidies | G38: 50027 | H38: Super | J38: 55.04
A39: 43180 | B39: 430664 | C39: MEDINA | D39: Margarita | E39: 04 | F39: Earnings | G39: 50002 | H39: Rate P - Other | I39: 5 | J39: 226.4
A40: 43180 | B40: 430664 | C40: MEDINA | D40: Margarita | E40: 04 | F40: Oncosts | G40: 50018 | H40: Oncosts | J40: 15.51
...

Sheet Split_by_advisor
A1: Period End Date | B1: Emp. No. | C1: Surname | D1: Preferred Name | E1: Job Number | F1: GL Record Type Description | G1: Account Number Prefix | H1: Paycode | I1: Salary Hours | J1: Amt$
A2: 43180 | B2: 429372 | C2: LOPEZ | D2: Angelica | E2: 04 | F2: Earnings | G2: 50002 | H2: Rate P - Other | I2: 5 | J2: 226.4
A3: 43180 | B3: 429372 | C3: LOPEZ | D3: Angelica | E3: 04 | F3: Oncosts | G3: 50018 | H3: Oncosts | J3: 15.51
A4: 43180 | B4: 429372 | C4: LOPEZ | D4: Angelica | E4: 04 | F4: Oncosts | G4: 50020 | H4: Oncosts | J4: 1.47
A5: 43180 | B5: 429372 | C5: LOPEZ | D5: Angelica | E5: 04 | F5: Oncosts | G5: 50021 | H5: Oncosts | J5: 2.83
A6: 43180 | B6: 429372 | C6: LOPEZ | D6: Angelica | E6: 04 | F6: Subsidies | G6: 50016 | H6: Super | J6: 21.51
A7: 43194 | B7: 429372 | C7: LOPEZ | D7: Angelica | E7: 04 | F7: Earnings | G7: 50002 | H7: Rate P - Other | I7: 5 | J7: 226.4
A8: 43194 | B8: 429372 | C8: LOPEZ | D8: Angelica | E8: 04 | F8: Oncosts | G8: 50018 | H8: Oncosts | J8: 15.51
A9: 43194 | B9: 429372 | C9: LOPEZ | D9: Angelica | E9: 04 | F9: Oncosts | G9: 50021 | H9: Oncosts | J9: 2.83
A10: 43208 | B10: 429372 | C10: LOPEZ | D10: Angelica | E10: 04 | F10: Oncosts | G10: 50020 | H10: Oncosts | J10: 1.47
A11: 43208 | B11: 429372 | C11: LOPEZ | D11: Angelica | E11: 04 | F11: Subsidies | G11: 50016 | H11: Super | J11: 21.51
A12: 43222 | B12: 429372 | C12: LOPEZ | D12: Angelica | E12: 04 | F12: Earnings | G12: 50002 | H12: Rate P - Other | I12: 10 | J12: 452.78
A13: 43222 | B13: 429372 | C13: LOPEZ | D13: Angelica | E13: 04 | F13: Oncosts | G13: 50018 | H13: Oncosts | J13: 31.02
A14: 43222 | B14: 429372 | C14: LOPEZ | D14: Angelica | E14: 04 | F14: Oncosts | G14: 50020 | H14: Oncosts | J14: 2.95
A15: 43222 | B15: 429372 | C15: LOPEZ | D15: Angelica | E15: 04 | F15: Oncosts | G15: 50021 | H15: Oncosts | J15: 5.66
A16: 43222 | B16: 429372 | C16: LOPEZ | D16: Angelica | E16: 04 | F16: Subsidies | G16: 50016 | H16: Super | J16: 43.01
A17: 43236 | B17: 429372 | C17: LOPEZ | D17: Angelica | E17: 04 | F17: Earnings | G17: 50002 | H17: Rate O - Marking | I17: 22.5 | J17: 1215.87
A18: 43236 | B18: 429372 | C18: LOPEZ | D18: Angelica | E18: 04 | F18: Oncosts | G18: 50018 | H18: Oncosts | J18: 83.29
A19: 43236 | B19: 429372 | C19: LOPEZ | D19: Angelica | E19: 04 | F19: Oncosts | G19: 50020 | H19: Oncosts | J19: 7.91
A20: 43236 | B20: 429372 | C20: LOPEZ | D20: Angelica | E20: 04 | F20: Oncosts | G20: 50021 | H20: Oncosts | J20: 15.19
A21: 43236 | B21: 429372 | C21: LOPEZ | D21: Angelica | E21: 04 | F21: Subsidies | G21: 50016 | H21: Super | J21: 115.51
A22: 43250 | B22: 429372 | C22: LOPEZ | D22: Angelica | E22: 04 | F22: Earnings | G22: 50002 | H22: Rate O - Marking | I22: -22.5 | J22: -1215.87
A23: 43250 | B23: 429372 | C23: LOPEZ | D23: Angelica | E23: 04 | F23: Earnings | G23: 50002 | H23: Rate P - Other | I23: 52.5 | J23: 2377.15
A24: 43250 | B24: 429372 | C24: LOPEZ | D24: Angelica | E24: 04 | F24: Earnings | G24: 50002 | H24: Rate Q - Other | I24: 25 | J24: 1350.96
A25: 43250 | B25: 429372 | C25: LOPEZ | D25: Angelica | E25: 04 | F25: Oncosts | G25: 50018 | H25: Oncosts | J25: 172.08
A26: 43250 | B26: 429372 | C26: LOPEZ | D26: Angelica | E26: 04 | F26: Oncosts | G26: 50020 | H26: Oncosts | J26: 17.82
A27: 43250 | B27: 429372 | C27: LOPEZ | D27: Angelica | E27: 04 | F27: Oncosts | G27: 50021 | H27: Oncosts | J27: 31.4
A28: 43250 | B28: 429372 | C28: LOPEZ | D28: Angelica | E28: 04 | F28: Subsidies | G28: 50016 | H28: Super | J28: 260.17
A29: 43264 | B29: 429372 | C29: LOPEZ | D29: Angelica | E29: 04 | F29: Earnings | G29: 50002 | H29: Rate P - Other | I29: 30 | J29: 1358.37
A30: 43264 | B30: 429372 | C30: LOPEZ | D30: Angelica | E30: 04 | F30: Oncosts | G30: 50018 | H30: Oncosts | J30: 93.04
A31: 43264 | B31: 429372 | C31: LOPEZ | D31: Angelica | E31: 04 | F31: Oncosts | G31: 50020 | H31: Oncosts | J31: 8.84
A32: 43264 | B32: 429372 | C32: LOPEZ | D32: Angelica | E32: 04 | F32: Oncosts | G32: 50021 | H32: Oncosts | J32: 16.98
A33: 43264 | B33: 429372 | C33: LOPEZ | D33: Angelica | E33: 04 | F33: Subsidies | G33: 50016 | H33: Super | J33: 129.05
A34: 43278 | B34: 429372 | C34: LOPEZ | D34: Angelica | E34: 04 | F34: Earnings | G34: 50002 | H34: Rate P - Other | I34: 30 | J34: 1358.37
A35: 43278 | B35: 429372 | C35: LOPEZ | D35: Angelica | E35: 04 | F35: Oncosts | G35: 50018 | H35: Oncosts | J35: 93.04
A36: 43278 | B36: 429372 | C36: LOPEZ | D36: Angelica | E36: 04 | F36: Oncosts | G36: 50020 | H36: Oncosts | J36: 8.84
A37: 43278 | B37: 429372 | C37: LOPEZ | D37: Angelica | E37: 04 | F37: Oncosts | G37: 50021 | H37: Oncosts | J37: 16.98
